Workbook

Sheet Longitude and Latitude
A1: Kabupaten Kota | B1: Latitude | C1: Longitude
A2: ACEH | B2: 4.695135 | C2: 96.749399
A3: Simeulue | B3: 2.583333 | C3: 96.083333
A4: Aceh Singkil | B4: 2.3589459 | C4: 97.87216
A5: Aceh Selatan | B5: 3.3115056 | C5: 97.351656
A6: Aceh Tenggara | B6: 3.3088666 | C6: 97.698227
A7: Aceh Timur | B7: 5.255443 | C7: 95.988546
A8: Aceh Tengah | B8: 4.4482641 | C8: 96.8351
A9: Aceh Barat | B9: 4.4542745 | C9: 96.152698
A10: Aceh Besar | B10: 5.4529168 | C10: 95.477781
A11: Pidie | B11: 5.0742659 | C11: 95.940971
A12: Bireuen | B12: 5.18254 | C12: 96.89005
A13: Aceh Utara | B13: 4.9786331 | C13: 97.222142
... A573: Jayawijaya | B573: -4.52167 | C573: 140.29541
A574: Lanny Jaya
A575: Tolikara
A576: Mamberamo Tengah
A577: Yalimo
A578: Yahukimo
A579: Pegunungan Bintang

Sheet DataAll
A1: Kabupaten Kota | B1: IPG | D1: Kabupaten Kota | E1: IDG | G1: Kabupaten Kota | H1: IKG | J1: Kabupaten Kota | K1: Keterlibatan Perempuan di Parlemen (Persen) | M1: Kabupaten Kota | N1: Perempuan sebagai Tenaga Profesional (Persen) | P1: Kabupaten/Kota | Q1: Prevalensi Ketidakcukupan Konsumsi Pangan (Persen) Per Kabupaten/kota (Persen) | S1: Kabupaten Kota | T1: Proporsi Perempuan Pernah Kawin 15-49 tahun yang Melahirkan Anak Lahir Hidup Yang Pertama Kali Berumur Kurang dari 20 tahun Menurut Kabupaten/Kota | V1: Kabupaten Kota | W1: Sumbangan Pendapatan Perempuan (Persen) | Y1: Provinsi/Kabupaten/Kota | Z1: Angka Kelahiran Total | AC1: NAMA DAERAH | AD1: DAUPendidikan | AE1: DAUKesehatan | AF1: DAUPekerjaanumum | AI1: Daerah | AJ1: AKB | AL1: Nama Wilayah | AM1: PPM | AO1: Daerah | AP1: AHHL | AQ1: AHHP | AS1: Daerah | AT1: RLSL | AU1: RLSP | AW1: Daerah | AX1: PSMA
A2: ACEH | B2: 92.55 | D2: ACEH | E2: 63.56 | G2: ACEH | H2: 0.489 | J2: ACEH | K2: 11.11 | M2: ACEH | N2: 55.77 | P2: Simeulue | Q2: 10.91 | S2: ACEH | T2: 0.209 | V2: ACEH | W2: 34.5 | Y2: ACEH | Z2: 2.42 | AC2: Aceh | AD2: 226421030 | AE2: 41187010 | AF2: 23846273 | AI2: ACEH | AJ2: 22.88 | AL2: ACEH | AM2: 14.45 | AO2: ACEH | AP2: 68.42 | AQ2: 72.35 | AS2: ACEH | AT2: 9.7 | AU2: 9.4 | AW2: ACEH | AX2: 44.57
A3: Simeulue | B3: 79.41 | D3: SIMEULUE | E3: 64.79 | G3: Simeulue | H3: 0.302 | J3: SIMEULUE | K3: 20 | M3: SIMEULUE | N3: 52.38 | P3: Aceh Singkil | Q3: 7.31 | S3: Simeulue | T3: 0.261 | V3: SIMEULUE | W3: 24.04 | Y3: SIMEULUE | Z3: 2.71 | AC3: Aceh Barat | AD3: 63513911 | AE3: 31594492 | AF3: 17535407 | AI3: SIMEULUE | AJ3: 38.9 | AL3: Simeulue | AM3: 17.92 | AO3: Simeulue | AP3: 63.72 | AQ3: 67.59 | AS3: Simeulue | AT3: 10.15 | AU3: 9.37 | AW3: Simeulue | AX3: 42.67
A4: Aceh Singkil | B4: 85.23 | D4: ACEH SINGKIL | E4: 59.84 | G4: Aceh Singkil | H4: 0.525 | J4: ACEH SINGKIL | K4: 12 | M4: ACEH SINGKIL | N4: 58.41 | P4: Aceh Selatan | Q4: 13.7 | S4: Aceh Singkil | T4: 0.279 | V4: ACEH SINGKIL | W4: 29.1 | Y4: ACEH SINGKIL | Z4: 3.04 | AC4: Aceh Besar | AD4: 74512082 | AE4: 44604335 | AF4: 21647988 | AI4: ACEH SINGKIL | AJ4: 39.3 | AL4: Aceh Singkil | AM4: 19.15 | AO4: Aceh Singkil | AP4: 65.84 | AQ4: 69.82 | AS4: Aceh Singkil | AT4: 9.03 | AU4: 8.28 | AW4: Aceh Singkil | AX4: 38.62
A5: Aceh Selatan | B5: 92.12 | D5: ACEH SELATAN | E5: 57.65 | G5: Aceh Selatan | H5: 0.457 | J5: ACEH SELATAN | K5: 10 | M5: ACEH SELATAN | N5: 52.3 | P5: Aceh Tenggara | Q5: 12.97 | S5: Aceh Selatan | T5: 0.219 | V5: ACEH SELATAN | W5: 28.87 | Y5: ACEH SELATAN | Z5: 2.39 | AC5: Aceh Selatan | AD5: 70561182 | AE5: 42635523 | AF5: 43717592 | AI5: ACEH SELATAN | AJ5: 35.8 | AL5: Aceh Selatan | AM5: 12.1 | AO5: Aceh Selatan | AP5: 62.94 | AQ5: 66.78 | AS5: Aceh Selatan | AT5: 9.23 | AU5: 8.45 | AW5: Aceh Selatan | AX5: 34.83
A6: Aceh Tenggara | B6: 93.28 | D6: ACEH TENGGARA | E6: 59.4 | G6: Aceh Tenggara | H6: 0.519 | J6: ACEH TENGGARA | K6: 10 | M6: ACEH TENGGARA | N6: 53.83 | P6: Aceh Timur | Q6: 8.61 | S6: Aceh Tenggara | T6: 0.259 | V6: ACEH TENGGARA | W6: 31.46 | Y6: ACEH TENGGARA | Z6: 2.71 | AC6: Aceh Singkil | AD6: 56313869 | AE6: 28588767 | AF6: 15724946 | AI6: ACEH TENGGARA | AJ6: 25.45 | AL6: Aceh Tenggara | AM6: 12.45 | AO6: Aceh Tenggara | AP6: 66.71 | AQ6: 70.69 | AS6: Aceh Tenggara | AT6: 10.39 | AU6: 9.81 | AW6: Aceh Tenggara | AX6: 47.54
A7: Aceh Timur | B7: 86.98 | D7: ACEH TIMUR | E7: 57.52 | G7: Aceh Timur | H7: 0.548 | J7: ACEH TIMUR | K7: 10 | M7: ACEH TIMUR | N7: 52.03 | P7: Aceh Tengah | Q7: 8.61 | S7: Aceh Timur | T7: 0.229 | V7: ACEH TIMUR | W7: 29.09 | Y7: ACEH TIMUR | Z7: 2.41 | AC7: Aceh Tengah | AD7: 61703899 | AE7: 32336706 | AF7: 18983329 | AI7: ACEH TIMUR | AJ7: 26.75 | AL7: Aceh Timur | AM7: 13.39 | AO7: Aceh Timur | AP7: 67.14 | AQ7: 71.1 | AS7: Aceh Timur | AT7: 8.6 | AU7: 8.38 | AW7: Aceh Timur | AX7: 31.23
A8: Aceh Tengah | B8: 97.5 | D8: ACEH TENGAH | E8: 71.78 | G8: Aceh Tengah | H8: 0.507 | J8: ACEH TENGAH | K8: 16.67 | M8: ACEH TENGAH | N8: 55.93 | P8: Aceh Barat | Q8: 6.16 | S8: Aceh Tengah | T8: 0.263 | V8: ACEH TENGAH | W8: 37.41 | Y8: ACEH TENGAH | Z8: 2.51 | AC8: Aceh Tenggara | AD8: 74005116 | AE8: 27378623 | AF8: 44244837 | AI8: ACEH TENGAH | AJ8: 25.43 | AL8: Aceh Tengah | AM8: 14.38 | AO8: Aceh Tengah | AP8: 67.25 | AQ8: 71.21 | AS8: Aceh Tengah | AT8: 10.06 | AU8: 9.72 | AW8: Aceh Tengah | AX8: 47.92
A9: Aceh Barat | B9: 86.36 | D9: ACEH BARAT | E9: 56.86 | G9: Aceh Barat | H9: 0.404 | J9: ACEH BARAT | K9: 8 | M9: ACEH BARAT | N9: 48.63 | P9: Aceh Besar | Q9: 8.58 | S9: Aceh Barat | T9: 0.223 | V9: ACEH BARAT | W9: 29.56 | Y9: ACEH BARAT | Z9: 2.3 | AC9: Aceh Timur | AD9: 101353857 | AE9: 42624136 | AF9: 48622684 | AI9: ACEH BARAT | AJ9: 29.48 | AL9: Aceh Barat | AM9: 17.86 | AO9: Aceh Barat | AP9: 66.4 | AQ9: 70.38 | AS9: Aceh Barat | AT9: 10.16 | AU9: 9.8 | AW9: Aceh Barat | AX9: 48.3
A10: Aceh Besar | B10: 95.29 | D10: ACEH BESAR | E10: 47.2 | G10: Aceh Besar | H10: 0.5 | J10: ACEH BESAR | K10: 2.86 | M10: ACEH BESAR | N10: 57.67 | P10: Pidie | Q10: 9.12 | S10: Aceh Besar | T10: 0.182 | V10: ACEH BESAR | W10: 25.24 | Y10: ACEH BESAR | Z10: 2.25 | AC10: Aceh Utara | AD10: 120438845 | AE10: 50724907 | AF10: 40627054 | AI10: ACEH BESAR | AJ10: 22.41 | AL10: Aceh Besar | AM10: 13.38 | AO10: Aceh Besar | AP10: 68.22 | AQ10: 72.16 | AS10: Aceh Besar | AT10: 10.56 | AU10: 10.36 | AW10: Aceh Besar | AX10: 56.44
A11: Pidie | B11: 93.92 | D11: PIDIE | E11: 66.3 | G11: Pidie | H11: 0.288 | J11: PIDIE | K11: 17.5 | M11: PIDIE | N11: 59.02 | P11: Bireuen | Q11: 7.62 | S11: Pidie | T11: 0.127 | V11: PIDIE | W11: 32.01 | Y11: PIDIE | Z11: 2.35 | AC11: Bireuen | AD11: 97741728 | AE11: 31613111 | AF11: 20623557 | AI11: PIDIE | AJ11: 39.41 | AL11: Pidie | AM11: 18.78 | AO11: Pidie | AP11: 65.36 | AQ11: 69.32 | AS11: Pidie | AT11: 9.43 | AU11: 8.73 | AW11: Pidie | AX11: 39.24
A12: Bireuen | B12: 95.08 | D12: BIREUEN | E12: 59.19 | G12: Bireuen | H12: 0.478 | J12: BIREUEN | K12: 7.5 | M12: BIREUEN | N12: 59.12 | P12: Aceh Utara | Q12: 14.24 | S12: Bireuen | T12: 0.195 | V12: BIREUEN | W12: 38.51 | Y12: BIREUEN | Z12: 2.44 | AC12: Pidie | AD12: 88899614 | AE12: 67861398 | AF12: 28716041 | AI12: BIREUEN | AJ12: 20.64 | AL12: Bireuen | AM12: 12.12 | AO12: Bireuen | AP12: 69.72 | AQ12: 73.7 | AS12: Bireuen | AT12: 9.39 | AU12: 9.3 | AW12: Bireuen | AX12: 40.37
A13: Aceh Utara | B13: 93.3 | D13: ACEH UTARA | E13: 49.18 | G13: Aceh Utara | H13: 0.558 | J13: ACEH UTARA | K13: 2.22 | M13: ACEH UTARA | N13: 67.37 | P13: Aceh Barat Daya | Q13: 9.64 | S13: Aceh Utara | T13: 0.248 | V13: ACEH UTARA | W13: 34.17 | Y13: ACEH UTARA | Z13: 2.32 | AC13: Simeulue | AD13: 41299762 | AE13: 29109492 | AF13: 27019646 | AI13: ACEH UTARA | AJ13: 26.08 | AL13: Aceh Utara | AM13: 16.64 | AO13: Aceh Utara | AP13: 67.21 | AQ13: 71.18 | AS13: Aceh Utara | AT13: 9.03 | AU13: 8.72 | AW13: Aceh Utara | AX13: 35.11
A14: Aceh Barat Daya | B14: 90.27 | D14: ACEH BARAT DAYA | E14: 50.62 | G14: Aceh Barat Daya | H14: 0.494 | J14: ACEH BARAT DAYA | K14: 4 | M14: ACEH BARAT DAYA | N14: 65.04 | P14: Gayo Lues | Q14: 9.18 | S14: Aceh Barat Daya | T14: 0.239 | V14: ACEH BARAT DAYA | W14: 30.25 | Y14: ACEH BARAT DAYA | Z14: 2.37 | AC14: Kota Banda Aceh | AD14: 32318056 | AE14: 20346153 | AF14: - | AI14: ACEH BARAT DAYA | AJ14: 35.37 | AL14: Aceh Barat Daya | AM14: 15.43 | AO14: Aceh Barat Daya | AP14: 63.6 | AQ14: 67.46 | AS14: Aceh Barat Daya | AT14: 8.96 | AU14: 8.66 | AW14: Aceh Barat Daya | AX14: 40.01
A15: Gayo Lues | B15: 89.63 | D15: GAYO LUES | E15: 57.31 | G15: Gayo Lues | H15: 0.604 | J15: GAYO LUES | K15: 5 | M15: GAYO LUES | N15: 46.82 | P15: Aceh Tamiang | Q15: 12.05 | S15: Gayo Lues | T15: 0.287 | V15: GAYO LUES | W15: 36.61 | Y15: GAYO LUES | Z15: 2.72 | AC15: Kota Sabang | AD15: 10899469 | AE15: 12672686 | AF15: 5201235 | AI15: GAYO LUES | AJ15: 41.76 | AL15: Gayo Lues | AM15: 18.82 | AO15: Gayo Lues | AP15: 64.02 | AQ15: 67.91 | AS15: Gayo Lues | AT15: 9.23 | AU15: 7.72 | AW15: Gayo Lues | AX15: 32.31
A16: Aceh Tamiang | B16: 82.38 | D16: ACEH TAMIANG | E16: 76.54 | G16: Aceh Tamiang | H16: 0.488 | J16: ACEH TAMIANG | K16: 36.67 | M16: ACEH TAMIANG | N16: 56.79 | P16: Nagan Raya | Q16: 3.43 | S16: Aceh Tamiang | T16: 0.196 | V16: ACEH TAMIANG | W16: 28.33 | Y16: ACEH TAMIANG | Z16: 2.38 | AC16: Kota Langsa | AD16: 46050723 | AE16: 23907568 | AF16: 6413027 | AI16: ACEH TAMIANG | AJ16: 20.86 | AL16: Aceh Tamiang | AM16: 12.51 | AO16: Aceh Tamiang | AP16: 68.12 | AQ16: 72.06 | AS16: Aceh Tamiang | AT16: 9.51 | AU16: 9.01 | AW16: Aceh Tamiang | AX16: 45.36
A17: Nagan Raya | B17: 91.02 | D17: NAGAN RAYA | E17: 63.54 | G17: Nagan Raya | H17: 0.486 | J17: NAGAN RAYA | K17: 16 | M17: NAGAN RAYA | N17: 53.61 | P17: Aceh Jaya | Q17: 9.44 | S17: Nagan Raya | T17: 0.279 | V17: NAGAN RAYA | W17: 27.74 | Y17: NAGAN RAYA | Z17: 2.34 | AC17: Kota Lhokseumawe | AD17: 38412003 | AE17: 16446054 | AF17: 4303514 | AI17: NAGAN RAYA | AJ17: 25.02 | AL17: Nagan Raya | AM17: 17.25 | AO17: Nagan Raya | AP17: 67.68 | AQ17: 71.63 | AS17: Nagan Raya | AT17: 9.2 | AU17: 8.73 | AW17: Nagan Raya | AX17: 37.11
A18: Aceh Jaya | B18: 89.8 | D18: ACEH JAYA | E18: 58.35 | G18: Aceh Jaya | H18: 0.464 | J18: ACEH JAYA | K18: 5 | M18: ACEH JAYA | N18: 57.08 | P18: Bener Meriah | Q18: 7.22 | S18: Aceh Jaya | T18: 0.308 | V18: ACEH JAYA | W18: 38.07 | Y18: ACEH JAYA | Z18: 2.77 | AC18: Gayo Lues | AD18: 49380059 | AE18: 26511451 | AF18: 53259897 | AI18: ACEH JAYA | AJ18: 32.99 | AL18: Aceh Jaya | AM18: 12.42 | AO18: Aceh Jaya | AP18: 65.62 | AQ18: 69.59 | AS18: Aceh Jaya | AT18: 8.93 | AU18: 8.63 | AW18: Aceh Jaya | AX18: 34.77
A19: Bener Meriah | B19: 96.76 | D19: BENER MERIAH | E19: 52.68 | G19: Bener Meriah | H19: 0.573 | J19: BENER MERIAH | K19: 4 | M19: BENER MERIAH | N19: 57.41 | P19: Pidie Jaya | Q19: 9.47 | S19: Bener Meriah | T19: 0.21 | V19: BENER MERIAH | W19: 30 | Y19: BENER MERIAH | Z19: 2.58 | AC19: Aceh Barat Daya | AD19: 50563751 | AE19: 29367292 | AF19: 26255738 | AI19: BENER MERIAH | AJ19: 26.14 | AL19: Bener Meriah | AM19: 18.31 | AO19: Bener Meriah | AP19: 67.71 | AQ19: 71.66 | AS19: Bener Meriah | AT19: 10.16 | AU19: 10.04 | AW19: Bener Meriah | AX19: 51.21
A20: Pidie Jaya | B20: 95.27 | D20: PIDIE JAYA | E20: 52.15 | G20: Pidie Jaya | H20: 0.786 | J20: PIDIE JAYA | K20: - | M20: PIDIE JAYA | N20: 52.84 | P20: Kota Banda Aceh | Q20: 5.47 | S20: Pidie Jaya | T20: 0.163 | V20: PIDIE JAYA | W20: 35.01 | Y20: PIDIE JAYA | Z20: 2.49 | AC20: Aceh Jaya | AD20: 40350524 | AE20: 26273628 | AF20: 27183536 | AI20: PIDIE JAYA | AJ20: 23.19 | AL20: Pidie Jaya | AM20: 18.4 | AO20: Pidie Jaya | AP20: 68.68 | AQ20: 72.61 | AS20: Pidie Jaya | AT20: 9.8 | AU20: 9.47 | AW20: Pidie Jaya | AX20: 43.16
A21: Kota Banda Aceh | B21: 96.19 | D21: KOTA BANDA ACEH | E21: 62.42 | G21: Kota Banda Aceh | H21: 0.335 | J21: KOTA BANDA ACEH | K21: 13.33 | M21: KOTA BANDA ACEH | N21: 50.42 | P21: Kota Sabang | Q21: 9.01 | S21: Kota Banda Aceh | T21: 0.082 | V21: KOTA BANDA ACEH | W21: 28.26 | Y21: KOTA BANDA ACEH | Z21: 2.04 | AC21: Nagan Raya | AD21: 56753563 | AE21: 25282183 | AF21: 21994791 | AI21: KOTA BANDA ACEH | AJ21: 14.36 | AL21: Kota Banda Aceh | AM21: 7.04 | AO21: Kota Banda Aceh | AP21: 70.07 | AQ21: 74.07 | AS21: Kota Banda Aceh | AT21: 13.14 | AU21: 12.87 | AW21: Kota Banda Aceh | AX21: 75.67
A22: Kota Sabang | B22: 95.64 | D22: KOTA SABANG | E22: 75.43 | G22: Kota Sabang | H22: 0.326 | J22: KOTA SABANG | K22: 25 | M22: KOTA SABANG | N22: 54.3 | P22: Kota Langsa | Q22: 9.89 | S22: Kota Sabang | T22: 0.147 | V22: KOTA SABANG | W22: 33 | Y22: KOTA SABANG | Z22: 2.43 | AC22: Aceh Tamiang | AD22: 50206519 | AE22: 27864631 | AF22: 21690659 | AI22: KOTA SABANG | AJ22: 21.87 | AL22: Kota Sabang | AM22: 14.59 | AO22: Kota Sabang | AP22: 69.05 | AQ22: 73 | AS22: Kota Sabang | AT22: 11.32 | AU22: 11.05 | AW22: Kota Sabang | AX22: 58.93
A23: Kota Langsa | B23: 95.77 | D23: KOTA LANGSA | E23: 65.54 | G23: Kota Langsa | H23: 0.467 | J23: KOTA LANGSA | K23: 20 | M23: KOTA LANGSA | N23: 49.34 | P23: Kota Lhokseumawe | Q23: 6.09 | S23: Kota Langsa | T23: 0.099 | V23: KOTA LANGSA | W23: 27.47 | Y23: KOTA LANGSA | Z23: 2.23 | AC23: Bener Meriah | AD23: 48229562 | AE23: 20340498 | AF23: 37933551 | AI23: KOTA LANGSA | AJ23: 18.31 | AL23: Kota Langsa | AM23: 10.53 | AO23: Kota Langsa | AP23: 67.85 | AQ23: 71.8 | AS23: Kota Langsa | AT23: 11.54 | AU23: 11.01 | AW23: Kota Langsa | AX23: 64.14
A24: Kota Lhokseumawe | B24: 95.73 | D24: KOTA LHOKSEUMAWE | E24: 65.7 | G24: Kota Lhokseumawe | H24: 0.303 | J24: KOTA LHOKSEUMAWE | K24: 24 | M24: KOTA LHOKSEUMAWE | N24: 57.04 | P24: Kota Subulussalam | Q24: 7.3 | S24: Kota Lhokseumawe | T24: 0.174 | V24: KOTA LHOKSEUMAWE | W24: 23.68 | Y24: KOTA LHOKSEUMAWE | Z24: 2.39 | AC24: Pidie Jaya | AD24: 29905018 | AE24: 23781682 | AF24: 18850150 | AI24: KOTA LHOKSEUMAWE | AJ24: 15.06 | AL24: Kota Lhokseumawe | AM24: 10.73 | AO24: Kota Lhokseumawe | AP24: 70.11 | AQ24: 74.11 | AS24: Kota Lhokseumawe | AT24: 11.46 | AU24: 11.19 | AW24: Kota Lhokseumawe | AX24: 61.25
A25: Kota Subulussalam | B25: 85.36 | D25: KOTA SUBULUSSALAM | E25: 67.84 | G25: Kota Subulussalam | H25: 0.583 | J25: KOTA SUBULUSSALAM | K25: 15 | M25: KOTA SUBULUSSALAM | N25: 61.47 | P25: Nias | Q25: 8.14 | S25: Kota Subulussalam | T25: 0.322 | V25: KOTA SUBULUSSALAM | W25: 36.28 | Y25: KOTA SUBULUSSALAM | Z25: 3.13 | AC25: Kota Subulussalam | AD25: 41480120 | AE25: 20607276 | AF25: 18032121 | AI25: KOTA SUBULUSSALAM | AJ25: 38.87 | AL25: Kota Subulussalam | AM25: 16.41 | AO25: Kota Subulussalam | AP25: 62.54 | AQ25: 66.37 | AS25: Kota Subulussalam | AT25: 8.88 | AU25: 7.94 | AW25: Kota Subulussalam | AX25: 34.02
A26: SUMATERA UTARA | B26: 91.31 | D26: SUMATERA UTARA | E26: 69.18 | G26: SUMATERA UTARA | H26: 0.425 | J26: SUMATERA UTARA | K26: 14 | M26: SUMATERA UTARA | N26: 53.95 | P26: Mandailing Natal | Q26: 9.03 | S26: SUMATERA UTARA | T26: 0.151 | V26: SUMATERA UTARA | W26: 36.21 | Y26: SUMATERA UTARA | Z26: 2.48 | AC26: Sumatera Utara | AD26: 406644265 | AE26: 56209232 | AF26: 19781378 | AI26: SUMATERA UTARA | AJ26: 21.37 | AL26: SUMATERA UTARA | AM26: 8.15 | AO26: SUMATERA UTARA | AP26: 68.06 | AQ26: 72 | AS26: SUMATERA UTARA | AT26: 10.02 | AU26: 9.63 | AW26: SUMATERA UTARA | AX26: 51.68
A27: Nias | B27: 91.05 | D27: NIAS | E27: 61.45 | G27: Nias | H27: 0.563 | J27: NIAS | K27: 8 | M27: NIAS | N27: 35.47 | P27: Tapanuli Selatan | Q27: 8.1 | S27: Nias | T27: 0.233 | V27: NIAS | W27: 50.32 | Y27: NIAS | Z27: 3.18 | AC27: Asahan | AD27: 110149371 | AE27: 54620516 | AF27: 23723021 | AI27: NIAS | AJ27: 28.95 | AL27: Nias | AM27: 15.1 | AO27: Nias | AP27: 68.42 | AQ27: 72.35 | AS27: Nias | AT27: 7.4 | AU27: 5.2 | AW27: Nias | AX27: 26.36
A28: Mandailing Natal | B28: 93.68 | D28: MANDAILING NATAL | E28: 73.73 | G28: Mandailing Natal | H28: 0.515 | J28: MANDAILING NATAL | K28: 15 | M28: MANDAILING NATAL | N28: 50.09 | P28: Tapanuli Tengah | Q28: 6.99 | S28: Mandailing Natal | T28: 0.222 | V28: MANDAILING NATAL | W28: 46.89 | Y28: MANDAILING NATAL | Z28: 3.04 | AC28: Dairi | AD28: 20387329 | AE28: 28732548 | AF28: 23537878 | AI28: MANDAILING NATAL | AJ28: 30.54 | AL28: Mandailing Natal | AM28: 8.86 | AO28: Mandailing Natal | AP28: 61.62 | AQ28: 65.42 | AS28: Mandailing Natal | AT28: 8.91 | AU28: 8.84 | AW28: Mandailing Natal | AX28: 38.56
A29: Tapanuli Selatan | B29: 90.63 | D29: TAPANULI SELATAN | E29: 71.61 | G29: Tapanuli Selatan | H29: 0.514 | J29: TAPANULI SELATAN | K29: 11.43 | M29: TAPANULI SELATAN | N29: 51.23 | P29: Tapanuli Utara | Q29: 7.05 | S29: Tapanuli Selatan | T29: 0.164 | V29: TAPANULI SELATAN | W29: 50.48 | Y29: TAPANULI SELATAN | Z29: 2.77 | AC29: Deli Serdang | AD29: 220653714 | AE29: 65703506 | AF29: 8180777 | AI29: TAPANULI SELATAN | AJ29: 30.2 | AL29: Tapanuli Selatan | AM29: 7.01 | AO29: Tapanuli Selatan | AP29: 63.67 | AQ29: 67.54 | AS29: Tapanuli Selatan | AT29: 9.83 | AU29: 9.12 | AW29: Tapanuli Selatan | AX29: 42.97
A30: Tapanuli Tengah | B30: 95.23 | D30: TAPANULI TENGAH | E30: 76.81 | G30: Tapanuli Tengah | H30: 0.453 | J30: TAPANULI TENGAH | K30: 20 | M30: TAPANULI TENGAH | N30: 55.23 | P30: Toba Samosir | Q30: 6.91 | S30: Tapanuli Tengah | T30: 0.201 | V30: TAPANULI TENGAH | W30: 43.94 | Y30: TAPANULI TENGAH | Z30: 2.92 | AC30: Karo | AD30: 94122727 | AE30: 25800051 | AF30: 18805061 | AI30: TAPANULI TENGAH | AJ30: 29.78 | AL30: Tapanuli Tengah | AM30: 11.5 | AO30: Tapanuli Tengah | AP30: 65.95 | AQ30: 69.94 | AS30: Tapanuli Tengah | AT30: 9.18 | AU30: 8.69 | AW30: Tapanuli Tengah | AX30: 41.48
A31: Tapanuli Utara | B31: 97.75 | D31: TAPANULI UTARA | E31: 63.82 | G31: Tapanuli Utara | H31: 0.292 | J31: TAPANULI UTARA | K31: 5.71 | M31: TAPANULI UTARA | N31: 51.81 | P31: Labuhan Batu | Q31: 7.38 | S31: Tapanuli Utara | T31: 0.071 | V31: TAPANULI UTARA | W31: 49.18 | Y31: TAPANULI UTARA | Z31: 2.87 | AC31: Labuhan batu | AD31: 87312475 | AE31: 38631288 | AF31: 13849130 | AI31: TAPANULI UTARA | AJ31: 19.68 | AL31: Tapanuli Utara | AM31: 8.54 | AO31: Tapanuli Utara | AP31: 67.64 | AQ31: 71.59 | AS31: Tapanuli Utara | AT31: 10.34 | AU31: 9.93 | AW31: Tapanuli Utara | AX31: 58.5
A32: Toba Samosir / Toba | B32: 98.32 | D32: TOBA SAMOSIR | E32: 61.53 | G32: Toba Samosir | H32: 0.505 | J32: TOBA SAMOSIR | K32: 3.33 | M32: TOBA SAMOSIR | N32: 51.86 | P32: Asahan | Q32: 8.65 | S32: Toba Samosir | T32: 0.097 | V32: TOBA SAMOSIR | W32: 46.96 | Y32: TOBA SAMOSIR | Z32: 2.97 | AC32: Langkat | AD32: 152222047 | AE32: 74082586 | AF32: 17271768 | AI32: TOBA SAMOSIR | AJ32: 19.3 | AL32: Toba Samosir | AM32: 8.04 | AO32: Toba Samosir / Toba | AP32: 69.31 | AQ32: 73.27 | AS32: Toba Samosir / Toba | AT32: 10.79 | AU32: 10.46 | AW32: Toba Samosir / Toba | AX32: 62.03
... A60: SUMATERA BARAT | B60: 94.93 | D60: SUMATERA BARAT | E60: 65.34 | G60: SUMATERA BARAT | H60: 0.425 | J60: SUMATERA BARAT | K60: 10.94 | M60: SUMATERA BARAT | N60: 61.04 | P60: Solok | Q60: 6.83 | S60: SUMATERA BARAT | T60: 0.165 | V60: SUMATERA BARAT | W60: 37.55 | Y60: SUMATERA BARAT | Z60: 2.46 | AC60: Sumatera Barat | AD60: 238094588 | AE60: 38286764 | AF60: 36420845 | AI60: SUMATERA BARAT | AJ60: 19.19 | AL60: SUMATERA BARAT | AM60: 5.95 | AO60: SUMATERA BARAT | AP60: 68.27 | AQ60: 72.21 | AS60: SUMATERA BARAT | AT60: 9.2 | AU60: 9.37 | AW60: SUMATERA BARAT | AX60: 49.08
A61: Kepulauan Mentawai | B61: 89.57 | D61: KEPULAUAN MENTAWAI | E61: 48.5 | G61: Kepulauan Mentawai | H61: 0.851 | J61: KEPULAUAN MENTAWAI | K61: - | M61: KEPULAUAN MENTAWAI | N61: 52.34 | P61: Sijunjung | Q61: 5.88 | S61: Kepulauan Mentawai | T61: 0.335 | V61: KEPULAUAN MENTAWAI | W61: 31.23 | Y61: KEPULAUAN MENTAWAI | Z61: 2.8 | AC61: Lima Puluh Kota | AD61: 43419818 | AE61: 40068708 | AF61: 36623906 | AI61: KEPULAUAN MENTAWAI | AJ61: 31.93 | AL61: Kepulauan Mentawai | AM61: 13.72 | AO61: Kepulauan Mentawai | AP61: 63.22 | AQ61: 67.07 | AS61: Kepulauan Mentawai | AT61: 8.36 | AU61: 7.29 | AW61: Kepulauan Mentawai | AX61: 28.15
A62: Pesisir Selatan | B62: 95.57 | D62: PESISIR SELATAN | E62: 53.79 | G62: Pesisir Selatan | H62: 0.482 | J62: PESISIR SELATAN | K62: 6.67 | M62: PESISIR SELATAN | N62: 70.15 | P62: Tanah Datar | Q62: 9.54 | S62: Pesisir Selatan | T62: 0.202 | V62: PESISIR SELATAN | W62: 33.81 | Y62: PESISIR SELATAN | Z62: 2.56 | AC62: Agam | AD62: 45935381 | AE62: 14606555 | AF62: 23097206 | AI62: PESISIR SELATAN | AJ62: 21.3 | AL62: Pesisir Selatan | AM62: 7.34 | AO62: Pesisir Selatan | AP62: 69.58 | AQ62: 73.55 | AS62: Pesisir Selatan | AT62: 8.61 | AU62: 8.58 | AW62: Pesisir Selatan | AX62: 45.64
A63: Solok | B63: 96.17 | D63: SOLOK | E63: 59.38 | G63: Solok | H63: 0.423 | J63: SOLOK | K63: 8.57 | M63: SOLOK | N63: 69.87 | P63: Padang Pariaman | Q63: 7.41 | S63: Solok | T63: 0.195 | V63: SOLOK | W63: 39.46 | Y63: SOLOK | Z63: 2.39 | AC63: Kepulauan Mentawai | AD63: 67812544 | AE63: 29600531 | AF63: 88227005 | AI63: SOLOK | AJ63: 27.87 | AL63: Solok | AM63: 7.13 | AO63: Solok | AP63: 67.63 | AQ63: 71.58 | AS63: Solok | AT63: 7.93 | AU63: 7.9 | AW63: Solok | AX63: 37.1
A64: Sijunjung | B64: 94.28 | D64: SIJUNJUNG | E64: 61.72 | G64: Sijunjung | H64: 0.465 | J64: SIJUNJUNG | K64: 13.33 | M64: SIJUNJUNG | N64: 58.97 | P64: Agam | Q64: 9.86 | S64: Sijunjung | T64: 0.24 | V64: SIJUNJUNG | W64: 28.55 | Y64: SIJUNJUNG | Z64: 2.51 | AC64: Padang Pariaman | AD64: 66069660 | AE64: 38665531 | AF64: 43720571 | AI64: SIJUNJUNG | AJ64: 26.68 | AL64: Sijunjung | AM64: 5.88 | AO64: Sijunjung | AP64: 65.09 | AQ64: 69.04 | AS64: Sijunjung | AT64: 8.66 | AU64: 8.55 | AW64: Sijunjung | AX64: 43.87
A65: Tanah Datar | B65: 97.73 | D65: TANAH DATAR | E65: 59.46 | G65: Tanah Datar | H65: 0.336 | J65: TANAH DATAR | K65: 8.57 | M65: TANAH DATAR | N65: 62.19 | P65: Lima Puluh Kota | Q65: 6.85 | S65: Tanah Datar | T65: 0.141 | V65: TANAH DATAR | W65: 35.54 | Y65: TANAH DATAR | Z65: 2.41 | AC65: Pasaman | AD65: 79882201 | AE65: 40837808 | AF65: 28385395 | AI65: TANAH DATAR | AJ65: 19.05 | AL65: Tanah Datar | AM65: 4.16 | AO65: Tanah Datar | AP65: 68.92 | AQ65: 72.86 | AS65: Tanah Datar | AT65: 8.78 | AU65: 9.22 | AW65: Tanah Datar | AX65: 46.7
A66: Padang Pariaman | B66: 93.32 | D66: PADANG PARIAMAN | E66: 47.79 | G66: Padang Pariaman | H66: 0.751 | J66: PADANG PARIAMAN | K66: - | M66: PADANG PARIAMAN | N66: 60.06 | P66: Pasaman | Q66: 8.67 | S66: Padang Pariaman | T66: 0.067 | V66: PADANG PARIAMAN | W66: 31.2 | Y66: PADANG PARIAMAN | Z66: 2.54 | AC66: Pesisir Selatan | AD66: 101903411 | AE66: 28706509 | AF66: 62836588 | AI66: PADANG PARIAMAN | AJ66: 19.05 | AL66: Padang Pariaman | AM66: 6.34 | AO66: Padang Pariaman | AP66: 67.77 | AQ66: 71.72 | AS66: Padang Pariaman | AT66: 8.7 | AU66: 8.11 | AW66: Padang Pariaman | AX66: 40.36
A67: Agam | B67: 97.19 | D67: AGAM | E67: 64.43 | G67: Agam | H67: 0.162 | J67: AGAM | K67: 8.89 | M67: AGAM | N67: 57.14 | P67: Solok Selatan | Q67: 8.01 | S67: Agam | T67: 0.07 | V67: AGAM | W67: 39.72 | Y67: AGAM | Z67: 2.55 | AC67: Sijunjung | AD67: 36681640 | AE67: 34450311 | AF67: 36994977 | AI67: AGAM | AJ67: 17.65 | AL67: Agam | AM67: 6.6 | AO67: Agam | AP67: 71.15 | AQ67: 75.41 | AS67: Agam | AT67: 9.09 | AU67: 9.33 | AW67: Agam | AX67: 49.9
...

Sheet Data
A1: Kabupaten/Kota | B1: IPG | C1: IDG | D1: IKG | E1: Wpar | F1: Wwork | G1: Unourish | H1: Childbirth | I1: Wsumbang | J1: TFR | K1: PPM | L1: AKB | M1: AHHL | N1: AHHP | O1: RLSL | P1: RLSP | Q1: PSMA | R1: Latitude | S1: Longitude | T1: Filter
A2: ACEH | B2: 92.55 | C2: {=INDEX(DataAll!$E$2:$E$555,MATCH(LOWER(Data!A2),LOWER(DataAll!$D$2:$D$555),0))} -> 63.56 | D2: {=INDEX(DataAll!$H$2:$H$579,MATCH(LOWER(Data!A2),LOWER(DataAll!$G$2:$G$555),0))} -> 0.489 | E2: {=INDEX(DataAll!$K$2:$K$579,MATCH(LOWER(Data!A2),LOWER(DataAll!$J$2:$J$555),0))} -> 11.11 | F2: {=INDEX(DataAll!$N$2:$N$555,MATCH(LOWER(Data!A2),LOWER(DataAll!$M$2:$M$555),0))} -> 55.77 | G2: {=INDEX(DataAll!$Q$2:$Q$555,MATCH(LOWER(Data!A2),LOWER(DataAll!$P$2:$P$555),0))} -> #N/A | H2: {=INDEX(DataAll!$T$2:$T$555,MATCH(LOWER(Data!A2),LOWER(DataAll!$S$2:$S$555),0))} -> 0.209 | I2: {=INDEX(DataAll!$W$2:$W$555,MATCH(LOWER(Data!A2),LOWER(DataAll!$V$2:$V$555),0))} -> 34.5 | J2: {=INDEX(DataAll!$Z$2:$Z$555,MATCH(LOWER(Data!A2),LOWER(DataAll!$Y$2:$Y$555),0))} -> 2.42 | K2: {=INDEX(DataAll!$AM$2:$AM$555,MATCH(LOWER(Data!A2),LOWER(DataAll!$AL$2:$AL$555),0))} -> 14.45 | L2: {=INDEX(DataAll!$AJ$2:$AJ$555,MATCH(LOWER(Data!A2),LOWER(DataAll!$AI$2:$AI$555),0))} -> 22.88 | M2: {=INDEX(DataAll!$AP$2:$AP$555,MATCH(LOWER(Data!A2),LOWER(DataAll!$AO$2:$AO$555),0))} -> 68.42 | N2: {=INDEX(DataAll!$AQ$2:$AQ$555,MATCH(LOWER(Data!A2),LOWER(DataAll!$AO$2:$AO$555),0))} -> 72.35 | O2: {=INDEX(DataAll!$AT$2:$AT$555,MATCH(LOWER(Data!A2),LOWER(DataAll!$AS$2:$AS$555),0))} -> 9.7 | P2: {=INDEX(DataAll!$AU$2:$AU$555,MATCH(LOWER(Data!A2),LOWER(DataAll!$AS$2:$AS$555),0))} -> 9.4 | Q2: {=INDEX(DataAll!$AX$2:$AX$556,MATCH(LOWER(Data!A2),LOWER(DataAll!$AW$2:$AW$556),0))} -> 44.57 | R2: {=INDEX('Longitude and Latitude'!$B$2:$B$579,MATCH(LOWER(Data!A2),LOWER('Longitude and Latitude'!$A$2:$A$579),0))} -> 4.695135 | S2: {=INDEX('Longitude and Latitude'!$C$2:$C$579,MATCH(LOWER(Data!A2),LOWER('Longitude and Latitude'!$A$2:$A$579),0))} -> 96.749399 | T2: =IF(EXACT(A2, UPPER(A2)), TRUE, FALSE) -> TRUE
A3: Simeulue | B3: 79.41 | C3: {=INDEX(DataAll!$E$2:$E$555,MATCH(LOWER(Data!A3),LOWER(DataAll!$D$2:$D$555),0))} -> 64.79 | D3: {=INDEX(DataAll!$H$2:$H$579,MATCH(LOWER(Data!A3),LOWER(DataAll!$G$2:$G$555),0))} -> 0.302 | E3: {=INDEX(DataAll!$K$2:$K$579,MATCH(LOWER(Data!A3),LOWER(DataAll!$J$2:$J$555),0))} -> 20 | F3: {=INDEX(DataAll!$N$2:$N$555,MATCH(LOWER(Data!A3),LOWER(DataAll!$M$2:$M$555),0))} -> 52.38 | G3: {=INDEX(DataAll!$Q$2:$Q$555,MATCH(LOWER(Data!A3),LOWER(DataAll!$P$2:$P$555),0))} -> 10.91 | H3: {=INDEX(DataAll!$T$2:$T$555,MATCH(LOWER(Data!A3),LOWER(DataAll!$S$2:$S$555),0))} -> 0.261 | I3: {=INDEX(DataAll!$W$2:$W$555,MATCH(LOWER(Data!A3),LOWER(DataAll!$V$2:$V$555),0))} -> 24.04 | J3: {=INDEX(DataAll!$Z$2:$Z$555,MATCH(LOWER(Data!A3),LOWER(DataAll!$Y$2:$Y$555),0))} -> 2.71 | K3: {=INDEX(DataAll!$AM$2:$AM$555,MATCH(LOWER(Data!A3),LOWER(DataAll!$AL$2:$AL$555),0))} -> 17.92 | L3: {=INDEX(DataAll!$AJ$2:$AJ$555,MATCH(LOWER(Data!A3),LOWER(DataAll!$AI$2:$AI$555),0))} -> 38.9 | M3: {=INDEX(DataAll!$AP$2:$AP$555,MATCH(LOWER(Data!A3),LOWER(DataAll!$AO$2:$AO$555),0))} -> 63.72 | N3: {=INDEX(DataAll!$AQ$2:$AQ$555,MATCH(LOWER(Data!A3),LOWER(DataAll!$AO$2:$AO$555),0))} -> 67.59 | O3: {=INDEX(DataAll!$AT$2:$AT$555,MATCH(LOWER(Data!A3),LOWER(DataAll!$AS$2:$AS$555),0))} -> 10.15 | P3: {=INDEX(DataAll!$AU$2:$AU$555,MATCH(LOWER(Data!A3),LOWER(DataAll!$AS$2:$AS$555),0))} -> 9.37 | Q3: {=INDEX(DataAll!$AX$2:$AX$556,MATCH(LOWER(Data!A3),LOWER(DataAll!$AW$2:$AW$556),0))} -> 42.67 | R3: {=INDEX('Longitude and Latitude'!$B$2:$B$579,MATCH(LOWER(Data!A3),LOWER('Longitude and Latitude'!$A$2:$A$579),0))} -> 2.583333 | S3: {=INDEX('Longitude and Latitude'!$C$2:$C$579,MATCH(LOWER(Data!A3),LOWER('Longitude and Latitude'!$A$2:$A$579),0))} -> 96.083333 | T3: =IF(EXACT(A3, UPPER(A3)), TRUE, FALSE) -> FALSE
A4: Aceh Singkil | B4: 85.23 | C4: {=INDEX(DataAll!$E$2:$E$555,MATCH(LOWER(Data!A4),LOWER(DataAll!$D$2:$D$555),0))} -> 59.84 | D4: {=INDEX(DataAll!$H$2:$H$579,MATCH(LOWER(Data!A4),LOWER(DataAll!$G$2:$G$555),0))} -> 0.525 | E4: {=INDEX(DataAll!$K$2:$K$579,MATCH(LOWER(Data!A4),LOWER(DataAll!$J$2:$J$555),0))} -> 12 | F4: {=INDEX(DataAll!$N$2:$N$555,MATCH(LOWER(Data!A4),LOWER(DataAll!$M$2:$M$555),0))} -> 58.41 | G4: {=INDEX(DataAll!$Q$2:$Q$555,MATCH(LOWER(Data!A4),LOWER(DataAll!$P$2:$P$555),0))} -> 7.31 | H4: {=INDEX(DataAll!$T$2:$T$555,MATCH(LOWER(Data!A4),LOWER(DataAll!$S$2:$S$555),0))} -> 0.279 | I4: {=INDEX(DataAll!$W$2:$W$555,MATCH(LOWER(Data!A4),LOWER(DataAll!$V$2:$V$555),0))} -> 29.1 | J4: {=INDEX(DataAll!$Z$2:$Z$555,MATCH(LOWER(Data!A4),LOWER(DataAll!$Y$2:$Y$555),0))} -> 3.04 | K4: {=INDEX(DataAll!$AM$2:$AM$555,MATCH(LOWER(Data!A4),LOWER(DataAll!$AL$2:$AL$555),0))} -> 19.15 | L4: {=INDEX(DataAll!$AJ$2:$AJ$555,MATCH(LOWER(Data!A4),LOWER(DataAll!$AI$2:$AI$555),0))} -> 39.3 | M4: {=INDEX(DataAll!$AP$2:$AP$555,MATCH(LOWER(Data!A4),LOWER(DataAll!$AO$2:$AO$555),0))} -> 65.84 | N4: {=INDEX(DataAll!$AQ$2:$AQ$555,MATCH(LOWER(Data!A4),LOWER(DataAll!$AO$2:$AO$555),0))} -> 69.82 | O4: {=INDEX(DataAll!$AT$2:$AT$555,MATCH(LOWER(Data!A4),LOWER(DataAll!$AS$2:$AS$555),0))} -> 9.03 | P4: {=INDEX(DataAll!$AU$2:$AU$555,MATCH(LOWER(Data!A4),LOWER(DataAll!$AS$2:$AS$555),0))} -> 8.28 | Q4: {=INDEX(DataAll!$AX$2:$AX$556,MATCH(LOWER(Data!A4),LOWER(DataAll!$AW$2:$AW$556),0))} -> 38.62 | R4: {=INDEX('Longitude and Latitude'!$B$2:$B$579,MATCH(LOWER(Data!A4),LOWER('Longitude and Latitude'!$A$2:$A$579),0))} -> 2.3589459 | S4: {=INDEX('Longitude and Latitude'!$C$2:$C$579,MATCH(LOWER(Data!A4),LOWER('Longitude and Latitude'!$A$2:$A$579),0))} -> 97.87216 | T4: =IF(EXACT(A4, UPPER(A4)), TRUE, FALSE) -> FALSE
A5: Aceh Selatan | B5: 92.12 | C5: {=INDEX(DataAll!$E$2:$E$555,MATCH(LOWER(Data!A5),LOWER(DataAll!$D$2:$D$555),0))} -> 57.65 | D5: {=INDEX(DataAll!$H$2:$H$579,MATCH(LOWER(Data!A5),LOWER(DataAll!$G$2:$G$555),0))} -> 0.457 | E5: {=INDEX(DataAll!$K$2:$K$579,MATCH(LOWER(Data!A5),LOWER(DataAll!$J$2:$J$555),0))} -> 10 | F5: {=INDEX(DataAll!$N$2:$N$555,MATCH(LOWER(Data!A5),LOWER(DataAll!$M$2:$M$555),0))} -> 52.3 | G5: {=INDEX(DataAll!$Q$2:$Q$555,MATCH(LOWER(Data!A5),LOWER(DataAll!$P$2:$P$555),0))} -> 13.7 | H5: {=INDEX(DataAll!$T$2:$T$555,MATCH(LOWER(Data!A5),LOWER(DataAll!$S$2:$S$555),0))} -> 0.219 | I5: {=INDEX(DataAll!$W$2:$W$555,MATCH(LOWER(Data!A5),LOWER(DataAll!$V$2:$V$555),0))} -> 28.87 | J5: {=INDEX(DataAll!$Z$2:$Z$555,MATCH(LOWER(Data!A5),LOWER(DataAll!$Y$2:$Y$555),0))} -> 2.39 | K5: {=INDEX(DataAll!$AM$2:$AM$555,MATCH(LOWER(Data!A5),LOWER(DataAll!$AL$2:$AL$555),0))} -> 12.1 | L5: {=INDEX(DataAll!$AJ$2:$AJ$555,MATCH(LOWER(Data!A5),LOWER(DataAll!$AI$2:$AI$555),0))} -> 35.8 | M5: {=INDEX(DataAll!$AP$2:$AP$555,MATCH(LOWER(Data!A5),LOWER(DataAll!$AO$2:$AO$555),0))} -> 62.94 | N5: {=INDEX(DataAll!$AQ$2:$AQ$555,MATCH(LOWER(Data!A5),LOWER(DataAll!$AO$2:$AO$555),0))} -> 66.78 | O5: {=INDEX(DataAll!$AT$2:$AT$555,MATCH(LOWER(Data!A5),LOWER(DataAll!$AS$2:$AS$555),0))} -> 9.23 | P5: {=INDEX(DataAll!$AU$2:$AU$555,MATCH(LOWER(Data!A5),LOWER(DataAll!$AS$2:$AS$555),0))} -> 8.45 | Q5: {=INDEX(DataAll!$AX$2:$AX$556,MATCH(LOWER(Data!A5),LOWER(DataAll!$AW$2:$AW$556),0))} -> 34.83 | R5: {=INDEX('Longitude and Latitude'!$B$2:$B$579,MATCH(LOWER(Data!A5),LOWER('Longitude and Latitude'!$A$2:$A$579),0))} -> 3.3115056 | S5: {=INDEX('Longitude and Latitude'!$C$2:$C$579,MATCH(LOWER(Data!A5),LOWER('Longitude and Latitude'!$A$2:$A$579),0))} -> 97.351656 | T5: =IF(EXACT(A5, UPPER(A5)), TRUE, FALSE) -> FALSE
A6: Aceh Tenggara | B6: 93.28 | C6: {=INDEX(DataAll!$E$2:$E$555,MATCH(LOWER(Data!A6),LOWER(DataAll!$D$2:$D$555),0))} -> 59.4 | D6: {=INDEX(DataAll!$H$2:$H$579,MATCH(LOWER(Data!A6),LOWER(DataAll!$G$2:$G$555),0))} -> 0.519 | E6: {=INDEX(DataAll!$K$2:$K$579,MATCH(LOWER(Data!A6),LOWER(DataAll!$J$2:$J$555),0))} -> 10 | F6: {=INDEX(DataAll!$N$2:$N$555,MATCH(LOWER(Data!A6),LOWER(DataAll!$M$2:$M$555),0))} -> 53.83 | G6: {=INDEX(DataAll!$Q$2:$Q$555,MATCH(LOWER(Data!A6),LOWER(DataAll!$P$2:$P$555),0))} -> 12.97 | H6: {=INDEX(DataAll!$T$2:$T$555,MATCH(LOWER(Data!A6),LOWER(DataAll!$S$2:$S$555),0))} -> 0.259 | I6: {=INDEX(DataAll!$W$2:$W$555,MATCH(LOWER(Data!A6),LOWER(DataAll!$V$2:$V$555),0))} -> 31.46 | J6: {=INDEX(DataAll!$Z$2:$Z$555,MATCH(LOWER(Data!A6),LOWER(DataAll!$Y$2:$Y$555),0))} -> 2.71 | K6: {=INDEX(DataAll!$AM$2:$AM$555,MATCH(LOWER(Data!A6),LOWER(DataAll!$AL$2:$AL$555),0))} -> 12.45 | L6: {=INDEX(DataAll!$AJ$2:$AJ$555,MATCH(LOWER(Data!A6),LOWER(DataAll!$AI$2:$AI$555),0))} -> 25.45 | M6: {=INDEX(DataAll!$AP$2:$AP$555,MATCH(LOWER(Data!A6),LOWER(DataAll!$AO$2:$AO$555),0))} -> 66.71 | N6: {=INDEX(DataAll!$AQ$2:$AQ$555,MATCH(LOWER(Data!A6),LOWER(DataAll!$AO$2:$AO$555),0))} -> 70.69 | O6: {=INDEX(DataAll!$AT$2:$AT$555,MATCH(LOWER(Data!A6),LOWER(DataAll!$AS$2:$AS$555),0))} -> 10.39 | P6: {=INDEX(DataAll!$AU$2:$AU$555,MATCH(LOWER(Data!A6),LOWER(DataAll!$AS$2:$AS$555),0))} -> 9.81 | Q6: {=INDEX(DataAll!$AX$2:$AX$556,MATCH(LOWER(Data!A6),LOWER(DataAll!$AW$2:$AW$556),0))} -> 47.54 | R6: {=INDEX('Longitude and Latitude'!$B$2:$B$579,MATCH(LOWER(Data!A6),LOWER('Longitude and Latitude'!$A$2:$A$579),0))} -> 3.3088666 | S6: {=INDEX('Longitude and Latitude'!$C$2:$C$579,MATCH(LOWER(Data!A6),LOWER('Longitude and Latitude'!$A$2:$A$579),0))} -> 97.698227 | T6: =IF(EXACT(A6, UPPER(A6)), TRUE, FALSE) -> FALSE
A7: Aceh Timur | B7: 86.98 | C7: {=INDEX(DataAll!$E$2:$E$555,MATCH(LOWER(Data!A7),LOWER(DataAll!$D$2:$D$555),0))} -> 57.52 | D7: {=INDEX(DataAll!$H$2:$H$579,MATCH(LOWER(Data!A7),LOWER(DataAll!$G$2:$G$555),0))} -> 0.548 | E7: {=INDEX(DataAll!$K$2:$K$579,MATCH(LOWER(Data!A7),LOWER(DataAll!$J$2:$J$555),0))} -> 10 | F7: {=INDEX(DataAll!$N$2:$N$555,MATCH(LOWER(Data!A7),LOWER(DataAll!$M$2:$M$555),0))} -> 52.03 | G7: {=INDEX(DataAll!$Q$2:$Q$555,MATCH(LOWER(Data!A7),LOWER(DataAll!$P$2:$P$555),0))} -> 8.61 | H7: {=INDEX(DataAll!$T$2:$T$555,MATCH(LOWER(Data!A7),LOWER(DataAll!$S$2:$S$555),0))} -> 0.229 | I7: {=INDEX(DataAll!$W$2:$W$555,MATCH(LOWER(Data!A7),LOWER(DataAll!$V$2:$V$555),0))} -> 29.09 | J7: {=INDEX(DataAll!$Z$2:$Z$555,MATCH(LOWER(Data!A7),LOWER(DataAll!$Y$2:$Y$555),0))} -> 2.41 | K7: {=INDEX(DataAll!$AM$2:$AM$555,MATCH(LOWER(Data!A7),LOWER(DataAll!$AL$2:$AL$555),0))} -> 13.39 | L7: {=INDEX(DataAll!$AJ$2:$AJ$555,MATCH(LOWER(Data!A7),LOWER(DataAll!$AI$2:$AI$555),0))} -> 26.75 | M7: {=INDEX(DataAll!$AP$2:$AP$555,MATCH(LOWER(Data!A7),LOWER(DataAll!$AO$2:$AO$555),0))} -> 67.14 | N7: {=INDEX(DataAll!$AQ$2:$AQ$555,MATCH(LOWER(Data!A7),LOWER(DataAll!$AO$2:$AO$555),0))} -> 71.1 | O7: {=INDEX(DataAll!$AT$2:$AT$555,MATCH(LOWER(Data!A7),LOWER(DataAll!$AS$2:$AS$555),0))} -> 8.6 | P7: {=INDEX(DataAll!$AU$2:$AU$555,MATCH(LOWER(Data!A7),LOWER(DataAll!$AS$2:$AS$555),0))} -> 8.38 | Q7: {=INDEX(DataAll!$AX$2:$AX$556,MATCH(LOWER(Data!A7),LOWER(DataAll!$AW$2:$AW$556),0))} -> 31.23 | R7: {=INDEX('Longitude and Latitude'!$B$2:$B$579,MATCH(LOWER(Data!A7),LOWER('Longitude and Latitude'!$A$2:$A$579),0))} -> 5.255443 | S7: {=INDEX('Longitude and Latitude'!$C$2:$C$579,MATCH(LOWER(Data!A7),LOWER('Longitude and Latitude'!$A$2:$A$579),0))} -> 95.988546 | T7: =IF(EXACT(A7, UPPER(A7)), TRUE, FALSE) -> FALSE
A8: Aceh Tengah | B8: 97.5 | C8: {=INDEX(DataAll!$E$2:$E$555,MATCH(LOWER(Data!A8),LOWER(DataAll!$D$2:$D$555),0))} -> 71.78 | D8: {=INDEX(DataAll!$H$2:$H$579,MATCH(LOWER(Data!A8),LOWER(DataAll!$G$2:$G$555),0))} -> 0.507 | E8: {=INDEX(DataAll!$K$2:$K$579,MATCH(LOWER(Data!A8),LOWER(DataAll!$J$2:$J$555),0))} -> 16.67 | F8: {=INDEX(DataAll!$N$2:$N$555,MATCH(LOWER(Data!A8),LOWER(DataAll!$M$2:$M$555),0))} -> 55.93 | G8: {=INDEX(DataAll!$Q$2:$Q$555,MATCH(LOWER(Data!A8),LOWER(DataAll!$P$2:$P$555),0))} -> 8.61 | H8: {=INDEX(DataAll!$T$2:$T$555,MATCH(LOWER(Data!A8),LOWER(DataAll!$S$2:$S$555),0))} -> 0.263 | I8: {=INDEX(DataAll!$W$2:$W$555,MATCH(LOWER(Data!A8),LOWER(DataAll!$V$2:$V$555),0))} -> 37.41 | J8: {=INDEX(DataAll!$Z$2:$Z$555,MATCH(LOWER(Data!A8),LOWER(DataAll!$Y$2:$Y$555),0))} -> 2.51 | K8: {=INDEX(DataAll!$AM$2:$AM$555,MATCH(LOWER(Data!A8),LOWER(DataAll!$AL$2:$AL$555),0))} -> 14.38 | L8: {=INDEX(DataAll!$AJ$2:$AJ$555,MATCH(LOWER(Data!A8),LOWER(DataAll!$AI$2:$AI$555),0))} -> 25.43 | M8: {=INDEX(DataAll!$AP$2:$AP$555,MATCH(LOWER(Data!A8),LOWER(DataAll!$AO$2:$AO$555),0))} -> 67.25 | N8: {=INDEX(DataAll!$AQ$2:$AQ$555,MATCH(LOWER(Data!A8),LOWER(DataAll!$AO$2:$AO$555),0))} -> 71.21 | O8: {=INDEX(DataAll!$AT$2:$AT$555,MATCH(LOWER(Data!A8),LOWER(DataAll!$AS$2:$AS$555),0))} -> 10.06 | P8: {=INDEX(DataAll!$AU$2:$AU$555,MATCH(LOWER(Data!A8),LOWER(DataAll!$AS$2:$AS$555),0))} -> 9.72 | Q8: {=INDEX(DataAll!$AX$2:$AX$556,MATCH(LOWER(Data!A8),LOWER(DataAll!$AW$2:$AW$556),0))} -> 47.92 | R8: {=INDEX('Longitude and Latitude'!$B$2:$B$579,MATCH(LOWER(Data!A8),LOWER('Longitude and Latitude'!$A$2:$A$579),0))} -> 4.4482641 | S8: {=INDEX('Longitude and Latitude'!$C$2:$C$579,MATCH(LOWER(Data!A8),LOWER('Longitude and Latitude'!$A$2:$A$579),0))} -> 96.8351 | T8: =IF(EXACT(A8, UPPER(A8)), TRUE, FALSE) -> FALSE
A9: Aceh Barat | B9: 86.36 | C9: {=INDEX(DataAll!$E$2:$E$555,MATCH(LOWER(Data!A9),LOWER(DataAll!$D$2:$D$555),0))} -> 56.86 | D9: {=INDEX(DataAll!$H$2:$H$579,MATCH(LOWER(Data!A9),LOWER(DataAll!$G$2:$G$555),0))} -> 0.404 | E9: {=INDEX(DataAll!$K$2:$K$579,MATCH(LOWER(Data!A9),LOWER(DataAll!$J$2:$J$555),0))} -> 8 | F9: {=INDEX(DataAll!$N$2:$N$555,MATCH(LOWER(Data!A9),LOWER(DataAll!$M$2:$M$555),0))} -> 48.63 | G9: {=INDEX(DataAll!$Q$2:$Q$555,MATCH(LOWER(Data!A9),LOWER(DataAll!$P$2:$P$555),0))} -> 6.16 | H9: {=INDEX(DataAll!$T$2:$T$555,MATCH(LOWER(Data!A9),LOWER(DataAll!$S$2:$S$555),0))} -> 0.223 | I9: {=INDEX(DataAll!$W$2:$W$555,MATCH(LOWER(Data!A9),LOWER(DataAll!$V$2:$V$555),0))} -> 29.56 | J9: {=INDEX(DataAll!$Z$2:$Z$555,MATCH(LOWER(Data!A9),LOWER(DataAll!$Y$2:$Y$555),0))} -> 2.3 | K9: {=INDEX(DataAll!$AM$2:$AM$555,MATCH(LOWER(Data!A9),LOWER(DataAll!$AL$2:$AL$555),0))} -> 17.86 | L9: {=INDEX(DataAll!$AJ$2:$AJ$555,MATCH(LOWER(Data!A9),LOWER(DataAll!$AI$2:$AI$555),0))} -> 29.48 | M9: {=INDEX(DataAll!$AP$2:$AP$555,MATCH(LOWER(Data!A9),LOWER(DataAll!$AO$2:$AO$555),0))} -> 66.4 | N9: {=INDEX(DataAll!$AQ$2:$AQ$555,MATCH(LOWER(Data!A9),LOWER(DataAll!$AO$2:$AO$555),0))} -> 70.38 | O9: {=INDEX(DataAll!$AT$2:$AT$555,MATCH(LOWER(Data!A9),LOWER(DataAll!$AS$2:$AS$555),0))} -> 10.16 | P9: {=INDEX(DataAll!$AU$2:$AU$555,MATCH(LOWER(Data!A9),LOWER(DataAll!$AS$2:$AS$555),0))} -> 9.8 | Q9: {=INDEX(DataAll!$AX$2:$AX$556,MATCH(LOWER(Data!A9),LOWER(DataAll!$AW$2:$AW$556),0))} -> 48.3 | R9: {=INDEX('Longitude and Latitude'!$B$2:$B$579,MATCH(LOWER(Data!A9),LOWER('Longitude and Latitude'!$A$2:$A$579),0))} -> 4.4542745 | S9: {=INDEX('Longitude and Latitude'!$C$2:$C$579,MATCH(LOWER(Data!A9),LOWER('Longitude and Latitude'!$A$2:$A$579),0))} -> 96.152698 | T9: =IF(EXACT(A9, UPPER(A9)), TRUE, FALSE) -> FALSE
A10: Aceh Besar | B10: 95.29 | C10: {=INDEX(DataAll!$E$2:$E$555,MATCH(LOWER(Data!A10),LOWER(DataAll!$D$2:$D$555),0))} -> 47.2 | D10: {=INDEX(DataAll!$H$2:$H$579,MATCH(LOWER(Data!A10),LOWER(DataAll!$G$2:$G$555),0))} -> 0.5 | E10: {=INDEX(DataAll!$K$2:$K$579,MATCH(LOWER(Data!A10),LOWER(DataAll!$J$2:$J$555),0))} -> 2.86 | F10: {=INDEX(DataAll!$N$2:$N$555,MATCH(LOWER(Data!A10),LOWER(DataAll!$M$2:$M$555),0))} -> 57.67 | G10: {=INDEX(DataAll!$Q$2:$Q$555,MATCH(LOWER(Data!A10),LOWER(DataAll!$P$2:$P$555),0))} -> 8.58 | H10: {=INDEX(DataAll!$T$2:$T$555,MATCH(LOWER(Data!A10),LOWER(DataAll!$S$2:$S$555),0))} -> 0.182 | I10: {=INDEX(DataAll!$W$2:$W$555,MATCH(LOWER(Data!A10),LOWER(DataAll!$V$2:$V$555),0))} -> 25.24 | J10: {=INDEX(DataAll!$Z$2:$Z$555,MATCH(LOWER(Data!A10),LOWER(DataAll!$Y$2:$Y$555),0))} -> 2.25 | K10: {=INDEX(DataAll!$AM$2:$AM$555,MATCH(LOWER(Data!A10),LOWER(DataAll!$AL$2:$AL$555),0))} -> 13.38 | L10: {=INDEX(DataAll!$AJ$2:$AJ$555,MATCH(LOWER(Data!A10),LOWER(DataAll!$AI$2:$AI$555),0))} -> 22.41 | M10: {=INDEX(DataAll!$AP$2:$AP$555,MATCH(LOWER(Data!A10),LOWER(DataAll!$AO$2:$AO$555),0))} -> 68.22 | N10: {=INDEX(DataAll!$AQ$2:$AQ$555,MATCH(LOWER(Data!A10),LOWER(DataAll!$AO$2:$AO$555),0))} -> 72.16 | O10: {=INDEX(DataAll!$AT$2:$AT$555,MATCH(LOWER(Data!A10),LOWER(DataAll!$AS$2:$AS$555),0))} -> 10.56 | P10: {=INDEX(DataAll!$AU$2:$AU$555,MATCH(LOWER(Data!A10),LOWER(DataAll!$AS$2:$AS$555),0))} -> 10.36 | Q10: {=INDEX(DataAll!$AX$2:$AX$556,MATCH(LOWER(Data!A10),LOWER(DataAll!$AW$2:$AW$556),0))} -> 56.44 | R10: {=INDEX('Longitude and Latitude'!$B$2:$B$579,MATCH(LOWER(Data!A10),LOWER('Longitude and Latitude'!$A$2:$A$579),0))} -> 5.4529168 | S10: {=INDEX('Longitude and Latitude'!$C$2:$C$579,MATCH(LOWER(Data!A10),LOWER('Longitude and Latitude'!$A$2:$A$579),0))} -> 95.477781 | T10: =IF(EXACT(A10, UPPER(A10)), TRUE, FALSE) -> FALSE
A11: Pidie | B11: 93.92 | C11: {=INDEX(DataAll!$E$2:$E$555,MATCH(LOWER(Data!A11),LOWER(DataAll!$D$2:$D$555),0))} -> 66.3 | D11: {=INDEX(DataAll!$H$2:$H$579,MATCH(LOWER(Data!A11),LOWER(DataAll!$G$2:$G$555),0))} -> 0.288 | E11: {=INDEX(DataAll!$K$2:$K$579,MATCH(LOWER(Data!A11),LOWER(DataAll!$J$2:$J$555),0))} -> 17.5 | F11: {=INDEX(DataAll!$N$2:$N$555,MATCH(LOWER(Data!A11),LOWER(DataAll!$M$2:$M$555),0))} -> 59.02 | G11: {=INDEX(DataAll!$Q$2:$Q$555,MATCH(LOWER(Data!A11),LOWER(DataAll!$P$2:$P$555),0))} -> 9.12 | H11: {=INDEX(DataAll!$T$2:$T$555,MATCH(LOWER(Data!A11),LOWER(DataAll!$S$2:$S$555),0))} -> 0.127 | I11: {=INDEX(DataAll!$W$2:$W$555,MATCH(LOWER(Data!A11),LOWER(DataAll!$V$2:$V$555),0))} -> 32.01 | J11: {=INDEX(DataAll!$Z$2:$Z$555,MATCH(LOWER(Data!A11),LOWER(DataAll!$Y$2:$Y$555),0))} -> 2.35 | K11: {=INDEX(DataAll!$AM$2:$AM$555,MATCH(LOWER(Data!A11),LOWER(DataAll!$AL$2:$AL$555),0))} -> 18.78 | L11: {=INDEX(DataAll!$AJ$2:$AJ$555,MATCH(LOWER(Data!A11),LOWER(DataAll!$AI$2:$AI$555),0))} -> 39.41 | M11: {=INDEX(DataAll!$AP$2:$AP$555,MATCH(LOWER(Data!A11),LOWER(DataAll!$AO$2:$AO$555),0))} -> 65.36 | N11: {=INDEX(DataAll!$AQ$2:$AQ$555,MATCH(LOWER(Data!A11),LOWER(DataAll!$AO$2:$AO$555),0))} -> 69.32 | O11: {=INDEX(DataAll!$AT$2:$AT$555,MATCH(LOWER(Data!A11),LOWER(DataAll!$AS$2:$AS$555),0))} -> 9.43 | P11: {=INDEX(DataAll!$AU$2:$AU$555,MATCH(LOWER(Data!A11),LOWER(DataAll!$AS$2:$AS$555),0))} -> 8.73 | Q11: {=INDEX(DataAll!$AX$2:$AX$556,MATCH(LOWER(Data!A11),LOWER(DataAll!$AW$2:$AW$556),0))} -> 39.24 | R11: {=INDEX('Longitude and Latitude'!$B$2:$B$579,MATCH(LOWER(Data!A11),LOWER('Longitude and Latitude'!$A$2:$A$579),0))} -> 5.0742659 | S11: {=INDEX('Longitude and Latitude'!$C$2:$C$579,MATCH(LOWER(Data!A11),LOWER('Longitude and Latitude'!$A$2:$A$579),0))} -> 95.940971 | T11: =IF(EXACT(A11, UPPER(A11)), TRUE, FALSE) -> FALSE
A12: Bireuen | B12: 95.08 | C12: {=INDEX(DataAll!$E$2:$E$555,MATCH(LOWER(Data!A12),LOWER(DataAll!$D$2:$D$555),0))} -> 59.19 | D12: {=INDEX(DataAll!$H$2:$H$579,MATCH(LOWER(Data!A12),LOWER(DataAll!$G$2:$G$555),0))} -> 0.478 | E12: {=INDEX(DataAll!$K$2:$K$579,MATCH(LOWER(Data!A12),LOWER(DataAll!$J$2:$J$555),0))} -> 7.5 | F12: {=INDEX(DataAll!$N$2:$N$555,MATCH(LOWER(Data!A12),LOWER(DataAll!$M$2:$M$555),0))} -> 59.12 | G12: {=INDEX(DataAll!$Q$2:$Q$555,MATCH(LOWER(Data!A12),LOWER(DataAll!$P$2:$P$555),0))} -> 7.62 | H12: {=INDEX(DataAll!$T$2:$T$555,MATCH(LOWER(Data!A12),LOWER(DataAll!$S$2:$S$555),0))} -> 0.195 | I12: {=INDEX(DataAll!$W$2:$W$555,MATCH(LOWER(Data!A12),LOWER(DataAll!$V$2:$V$555),0))} -> 38.51 | J12: {=INDEX(DataAll!$Z$2:$Z$555,MATCH(LOWER(Data!A12),LOWER(DataAll!$Y$2:$Y$555),0))} -> 2.44 | K12: {=INDEX(DataAll!$AM$2:$AM$555,MATCH(LOWER(Data!A12),LOWER(DataAll!$AL$2:$AL$555),0))} -> 12.12 | L12: {=INDEX(DataAll!$AJ$2:$AJ$555,MATCH(LOWER(Data!A12),LOWER(DataAll!$AI$2:$AI$555),0))} -> 20.64 | M12: {=INDEX(DataAll!$AP$2:$AP$555,MATCH(LOWER(Data!A12),LOWER(DataAll!$AO$2:$AO$555),0))} -> 69.72 | N12: {=INDEX(DataAll!$AQ$2:$AQ$555,MATCH(LOWER(Data!A12),LOWER(DataAll!$AO$2:$AO$555),0))} -> 73.7 | O12: {=INDEX(DataAll!$AT$2:$AT$555,MATCH(LOWER(Data!A12),LOWER(DataAll!$AS$2:$AS$555),0))} -> 9.39 | P12: {=INDEX(DataAll!$AU$2:$AU$555,MATCH(LOWER(Data!A12),LOWER(DataAll!$AS$2:$AS$555),0))} -> 9.3 | Q12: {=INDEX(DataAll!$AX$2:$AX$556,MATCH(LOWER(Data!A12),LOWER(DataAll!$AW$2:$AW$556),0))} -> 40.37 | R12: {=INDEX('Longitude and Latitude'!$B$2:$B$579,MATCH(LOWER(Data!A12),LOWER('Longitude and Latitude'!$A$2:$A$579),0))} -> 5.18254 | S12: {=INDEX('Longitude and Latitude'!$C$2:$C$579,MATCH(LOWER(Data!A12),LOWER('Longitude and Latitude'!$A$2:$A$579),0))} -> 96.89005 | T12: =IF(EXACT(A12, UPPER(A12)), TRUE, FALSE) -> FALSE
A13: Aceh Utara | B13: 93.3 | C13: {=INDEX(DataAll!$E$2:$E$555,MATCH(LOWER(Data!A13),LOWER(DataAll!$D$2:$D$555),0))} -> 49.18 | D13: {=INDEX(DataAll!$H$2:$H$579,MATCH(LOWER(Data!A13),LOWER(DataAll!$G$2:$G$555),0))} -> 0.558 | E13: {=INDEX(DataAll!$K$2:$K$579,MATCH(LOWER(Data!A13),LOWER(DataAll!$J$2:$J$555),0))} -> 2.22 | F13: {=INDEX(DataAll!$N$2:$N$555,MATCH(LOWER(Data!A13),LOWER(DataAll!$M$2:$M$555),0))} -> 67.37 | G13: {=INDEX(DataAll!$Q$2:$Q$555,MATCH(LOWER(Data!A13),LOWER(DataAll!$P$2:$P$555),0))} -> 14.24 | H13: {=INDEX(DataAll!$T$2:$T$555,MATCH(LOWER(Data!A13),LOWER(DataAll!$S$2:$S$555),0))} -> 0.248 | I13: {=INDEX(DataAll!$W$2:$W$555,MATCH(LOWER(Data!A13),LOWER(DataAll!$V$2:$V$555),0))} -> 34.17 | J13: {=INDEX(DataAll!$Z$2:$Z$555,MATCH(LOWER(Data!A13),LOWER(DataAll!$Y$2:$Y$555),0))} -> 2.32 | K13: {=INDEX(DataAll!$AM$2:$AM$555,MATCH(LOWER(Data!A13),LOWER(DataAll!$AL$2:$AL$555),0))} -> 16.64 | L13: {=INDEX(DataAll!$AJ$2:$AJ$555,MATCH(LOWER(Data!A13),LOWER(DataAll!$AI$2:$AI$555),0))} -> 26.08 | M13: {=INDEX(DataAll!$AP$2:$AP$555,MATCH(LOWER(Data!A13),LOWER(DataAll!$AO$2:$AO$555),0))} -> 67.21 | N13: {=INDEX(DataAll!$AQ$2:$AQ$555,MATCH(LOWER(Data!A13),LOWER(DataAll!$AO$2:$AO$555),0))} -> 71.18 | O13: {=INDEX(DataAll!$AT$2:$AT$555,MATCH(LOWER(Data!A13),LOWER(DataAll!$AS$2:$AS$555),0))} -> 9.03 | P13: {=INDEX(DataAll!$AU$2:$AU$555,MATCH(LOWER(Data!A13),LOWER(DataAll!$AS$2:$AS$555),0))} -> 8.72 | Q13: {=INDEX(DataAll!$AX$2:$AX$556,MATCH(LOWER(Data!A13),LOWER(DataAll!$AW$2:$AW$556),0))} -> 35.11 | R13: {=INDEX('Longitude and Latitude'!$B$2:$B$579,MATCH(LOWER(Data!A13),LOWER('Longitude and Latitude'!$A$2:$A$579),0))} -> 4.9786331 | S13: {=INDEX('Longitude and Latitude'!$C$2:$C$579,MATCH(LOWER(Data!A13),LOWER('Longitude and Latitude'!$A$2:$A$579),0))} -> 97.222142 | T13: =IF(EXACT(A13, UPPER(A13)), TRUE, FALSE) -> FALSE
... A497: Halmahera Tengah | B497: 90.46 | C497: {=INDEX(DataAll!$E$2:$E$555,MATCH(LOWER(Data!A497),LOWER(DataAll!$D$2:$D$555),0))} -> 53.32 | D497: {=INDEX(DataAll!$H$2:$H$579,MATCH(LOWER(Data!A497),LOWER(DataAll!$G$2:$G$555),0))} -> 0.606 | E497: {=INDEX(DataAll!$K$2:$K$579,MATCH(LOWER(Data!A497),LOWER(DataAll!$J$2:$J$555),0))} -> 5 | F497: {=INDEX(DataAll!$N$2:$N$555,MATCH(LOWER(Data!A497),LOWER(DataAll!$M$2:$M$555),0))} -> 43.86 | G497: {=INDEX(DataAll!$Q$2:$Q$555,MATCH(LOWER(Data!A497),LOWER(DataAll!$P$2:$P$555),0))} -> 15.3 | H497: {=INDEX(DataAll!$T$2:$T$555,MATCH(LOWER(Data!A497),LOWER(DataAll!$S$2:$S$555),0))} -> 0.288 | I497: {=INDEX(DataAll!$W$2:$W$555,MATCH(LOWER(Data!A497),LOWER(DataAll!$V$2:$V$555),0))} -> 30.86 | J497: {=INDEX(DataAll!$Z$2:$Z$555,MATCH(LOWER(Data!A497),LOWER(DataAll!$Y$2:$Y$555),0))} -> 2.75 | K497: {=INDEX(DataAll!$AM$2:$AM$555,MATCH(LOWER(Data!A497),LOWER(DataAll!$AL$2:$AL$555),0))} -> 11.44 | L497: {=INDEX(DataAll!$AJ$2:$AJ$555,MATCH(LOWER(Data!A497),LOWER(DataAll!$AI$2:$AI$555),0))} -> 38.9 | M497: {=INDEX(DataAll!$AP$2:$AP$555,MATCH(LOWER(Data!A497),LOWER(DataAll!$AO$2:$AO$555),0))} -> 63.18 | N497: {=INDEX(DataAll!$AQ$2:$AQ$555,MATCH(LOWER(Data!A497),LOWER(DataAll!$AO$2:$AO$555),0))} -> 67.03 | O497: {=INDEX(DataAll!$AT$2:$AT$555,MATCH(LOWER(Data!A497),LOWER(DataAll!$AS$2:$AS$555),0))} -> 9.55 | P497: {=INDEX(DataAll!$AU$2:$AU$555,MATCH(LOWER(Data!A497),LOWER(DataAll!$AS$2:$AS$555),0))} -> 9.02 | Q497: {=INDEX(DataAll!$AX$2:$AX$556,MATCH(LOWER(Data!A497),LOWER(DataAll!$AW$2:$AW$556),0))} -> 39.27 | R497: {=INDEX('Longitude and Latitude'!$B$2:$B$579,MATCH(LOWER(Data!A497),LOWER('Longitude and Latitude'!$A$2:$A$579),0))} -> 1.3121235 | S497: {=INDEX('Longitude and Latitude'!$C$2:$C$579,MATCH(LOWER(Data!A497),LOWER('Longitude and Latitude'!$A$2:$A$579),0))} -> 128.48499 | T497: =IF(EXACT(A497, UPPER(A497)), TRUE, FALSE) -> FALSE
A498: Kepulauan Sula | B498: 92.85 | C498: {=INDEX(DataAll!$E$2:$E$555,MATCH(LOWER(Data!A498),LOWER(DataAll!$D$2:$D$555),0))} -> 44.91 | D498: {=INDEX(DataAll!$H$2:$H$579,MATCH(LOWER(Data!A498),LOWER(DataAll!$G$2:$G$555),0))} -> 0.857 | F498: {=INDEX(DataAll!$N$2:$N$555,MATCH(LOWER(Data!A498),LOWER(DataAll!$M$2:$M$555),0))} -> 56.72 | G498: {=INDEX(DataAll!$Q$2:$Q$555,MATCH(LOWER(Data!A498),LOWER(DataAll!$P$2:$P$555),0))} -> 44.37 | H498: {=INDEX(DataAll!$T$2:$T$555,MATCH(LOWER(Data!A498),LOWER(DataAll!$S$2:$S$555),0))} -> 0.309 | I498: {=INDEX(DataAll!$W$2:$W$555,MATCH(LOWER(Data!A498),LOWER(DataAll!$V$2:$V$555),0))} -> 28.14 | J498: {=INDEX(DataAll!$Z$2:$Z$555,MATCH(LOWER(Data!A498),LOWER(DataAll!$Y$2:$Y$555),0))} -> 2.5 | K498: {=INDEX(DataAll!$AM$2:$AM$555,MATCH(LOWER(Data!A498),LOWER(DataAll!$AL$2:$AL$555),0))} -> 8.17 | L498: {=INDEX(DataAll!$AJ$2:$AJ$555,MATCH(LOWER(Data!A498),LOWER(DataAll!$AI$2:$AI$555),0))} -> 45.8 | M498: {=INDEX(DataAll!$AP$2:$AP$555,MATCH(LOWER(Data!A498),LOWER(DataAll!$AO$2:$AO$555),0))} -> 62.09 | N498: {=INDEX(DataAll!$AQ$2:$AQ$555,MATCH(LOWER(Data!A498),LOWER(DataAll!$AO$2:$AO$555),0))} -> 65.89 | O498: {=INDEX(DataAll!$AT$2:$AT$555,MATCH(LOWER(Data!A498),LOWER(DataAll!$AS$2:$AS$555),0))} -> 9.39 | P498: {=INDEX(DataAll!$AU$2:$AU$555,MATCH(LOWER(Data!A498),LOWER(DataAll!$AS$2:$AS$555),0))} -> 8.89 | Q498: {=INDEX(DataAll!$AX$2:$AX$556,MATCH(LOWER(Data!A498),LOWER(DataAll!$AW$2:$AW$556),0))} -> 32.35 | R498: {=INDEX('Longitude and Latitude'!$B$2:$B$579,MATCH(LOWER(Data!A498),LOWER('Longitude and Latitude'!$A$2:$A$579),0))} -> -1.8666667 | S498: {=INDEX('Longitude and Latitude'!$C$2:$C$579,MATCH(LOWER(Data!A498),LOWER('Longitude and Latitude'!$A$2:$A$579),0))} -> 125.36667 | T498: =IF(EXACT(A498, UPPER(A498)), TRUE, FALSE) -> FALSE
A499: Halmahera Selatan | B499: 87.58 | C499: {=INDEX(DataAll!$E$2:$E$555,MATCH(LOWER(Data!A499),LOWER(DataAll!$D$2:$D$555),0))} -> 47.19 | D499: {=INDEX(DataAll!$H$2:$H$579,MATCH(LOWER(Data!A499),LOWER(DataAll!$G$2:$G$555),0))} -> 0.615 | E499: {=INDEX(DataAll!$K$2:$K$579,MATCH(LOWER(Data!A499),LOWER(DataAll!$J$2:$J$555),0))} -> 6.67 | F499: {=INDEX(DataAll!$N$2:$N$555,MATCH(LOWER(Data!A499),LOWER(DataAll!$M$2:$M$555),0))} -> 51.12 | G499: {=INDEX(DataAll!$Q$2:$Q$555,MATCH(LOWER(Data!A499),LOWER(DataAll!$P$2:$P$555),0))} -> 30.48 | H499: {=INDEX(DataAll!$T$2:$T$555,MATCH(LOWER(Data!A499),LOWER(DataAll!$S$2:$S$555),0))} -> 0.355 | I499: {=INDEX(DataAll!$W$2:$W$555,MATCH(LOWER(Data!A499),LOWER(DataAll!$V$2:$V$555),0))} -> 21.19 | J499: {=INDEX(DataAll!$Z$2:$Z$555,MATCH(LOWER(Data!A499),LOWER(DataAll!$Y$2:$Y$555),0))} -> 2.86 | K499: {=INDEX(DataAll!$AM$2:$AM$555,MATCH(LOWER(Data!A499),LOWER(DataAll!$AL$2:$AL$555),0))} -> 5.68 | L499: {=INDEX(DataAll!$AJ$2:$AJ$555,MATCH(LOWER(Data!A499),LOWER(DataAll!$AI$2:$AI$555),0))} -> 43.06 | M499: {=INDEX(DataAll!$AP$2:$AP$555,MATCH(LOWER(Data!A499),LOWER(DataAll!$AO$2:$AO$555),0))} -> 64.59 | N499: {=INDEX(DataAll!$AQ$2:$AQ$555,MATCH(LOWER(Data!A499),LOWER(DataAll!$AO$2:$AO$555),0))} -> 68.5 | O499: {=INDEX(DataAll!$AT$2:$AT$555,MATCH(LOWER(Data!A499),LOWER(DataAll!$AS$2:$AS$555),0))} -> 8.54 | P499: {=INDEX(DataAll!$AU$2:$AU$555,MATCH(LOWER(Data!A499),LOWER(DataAll!$AS$2:$AS$555),0))} -> 7.82 | Q499: {=INDEX(DataAll!$AX$2:$AX$556,MATCH(LOWER(Data!A499),LOWER(DataAll!$AW$2:$AW$556),0))} -> 26.53 | R499: {=INDEX('Longitude and Latitude'!$B$2:$B$579,MATCH(LOWER(Data!A499),LOWER('Longitude and Latitude'!$A$2:$A$579),0))} -> 1.3121235 | S499: {=INDEX('Longitude and Latitude'!$C$2:$C$579,MATCH(LOWER(Data!A499),LOWER('Longitude and Latitude'!$A$2:$A$579),0))} -> 128.48499 | T499: =IF(EXACT(A499, UPPER(A499)), TRUE, FALSE) -> FALSE
A500: Halmahera Utara | B500: 90.03 | C500: {=INDEX(DataAll!$E$2:$E$555,MATCH(LOWER(Data!A500),LOWER(DataAll!$D$2:$D$555),0))} -> 68.4 | D500: {=INDEX(DataAll!$H$2:$H$579,MATCH(LOWER(Data!A500),LOWER(DataAll!$G$2:$G$555),0))} -> 0.56 | E500: {=INDEX(DataAll!$K$2:$K$579,MATCH(LOWER(Data!A500),LOWER(DataAll!$J$2:$J$555),0))} -> 20 | F500: {=INDEX(DataAll!$N$2:$N$555,MATCH(LOWER(Data!A500),LOWER(DataAll!$M$2:$M$555),0))} -> 45.45 | G500: {=INDEX(DataAll!$Q$2:$Q$555,MATCH(LOWER(Data!A500),LOWER(DataAll!$P$2:$P$555),0))} -> 31.22 | H500: {=INDEX(DataAll!$T$2:$T$555,MATCH(LOWER(Data!A500),LOWER(DataAll!$S$2:$S$555),0))} -> 0.317 | I500: {=INDEX(DataAll!$W$2:$W$555,MATCH(LOWER(Data!A500),LOWER(DataAll!$V$2:$V$555),0))} -> 29.62 | J500: {=INDEX(DataAll!$Z$2:$Z$555,MATCH(LOWER(Data!A500),LOWER(DataAll!$Y$2:$Y$555),0))} -> 2.48 | K500: {=INDEX(DataAll!$AM$2:$AM$555,MATCH(LOWER(Data!A500),LOWER(DataAll!$AL$2:$AL$555),0))} -> 4.62 | L500: {=INDEX(DataAll!$AJ$2:$AJ$555,MATCH(LOWER(Data!A500),LOWER(DataAll!$AI$2:$AI$555),0))} -> 29.03 | M500: {=INDEX(DataAll!$AP$2:$AP$555,MATCH(LOWER(Data!A500),LOWER(DataAll!$AO$2:$AO$555),0))} -> 68.19 | N500: {=INDEX(DataAll!$AQ$2:$AQ$555,MATCH(LOWER(Data!A500),LOWER(DataAll!$AO$2:$AO$555),0))} -> 72.13 | O500: {=INDEX(DataAll!$AT$2:$AT$555,MATCH(LOWER(Data!A500),LOWER(DataAll!$AS$2:$AS$555),0))} -> 9.22 | P500: {=INDEX(DataAll!$AU$2:$AU$555,MATCH(LOWER(Data!A500),LOWER(DataAll!$AS$2:$AS$555),0))} -> 8.25 | Q500: {=INDEX(DataAll!$AX$2:$AX$556,MATCH(LOWER(Data!A500),LOWER(DataAll!$AW$2:$AW$556),0))} -> 32.2 | R500: {=INDEX('Longitude and Latitude'!$B$2:$B$579,MATCH(LOWER(Data!A500),LOWER('Longitude and Latitude'!$A$2:$A$579),0))} -> 1.3121235 | S500: {=INDEX('Longitude and Latitude'!$C$2:$C$579,MATCH(LOWER(Data!A500),LOWER('Longitude and Latitude'!$A$2:$A$579),0))} -> 128.48499 | T500: =IF(EXACT(A500, UPPER(A500)), TRUE, FALSE) -> FALSE
A501: Halmahera Timur | B501: 82.59 | C501: {=INDEX(DataAll!$E$2:$E$555,MATCH(LOWER(Data!A501),LOWER(DataAll!$D$2:$D$555),0))} -> 50.05 | D501: {=INDEX(DataAll!$H$2:$H$579,MATCH(LOWER(Data!A501),LOWER(DataAll!$G$2:$G$555),0))} -> 0.597 | E501: {=INDEX(DataAll!$K$2:$K$579,MATCH(LOWER(Data!A501),LOWER(DataAll!$J$2:$J$555),0))} -> 5 | F501: {=INDEX(DataAll!$N$2:$N$555,MATCH(LOWER(Data!A501),LOWER(DataAll!$M$2:$M$555),0))} -> 52.42 | G501: {=INDEX(DataAll!$Q$2:$Q$555,MATCH(LOWER(Data!A501),LOWER(DataAll!$P$2:$P$555),0))} -> 32.27 | H501: {=INDEX(DataAll!$T$2:$T$555,MATCH(LOWER(Data!A501),LOWER(DataAll!$S$2:$S$555),0))} -> 0.316 | I501: {=INDEX(DataAll!$W$2:$W$555,MATCH(LOWER(Data!A501),LOWER(DataAll!$V$2:$V$555),0))} -> 25.63 | J501: {=INDEX(DataAll!$Z$2:$Z$555,MATCH(LOWER(Data!A501),LOWER(DataAll!$Y$2:$Y$555),0))} -> 2.73 | K501: {=INDEX(DataAll!$AM$2:$AM$555,MATCH(LOWER(Data!A501),LOWER(DataAll!$AL$2:$AL$555),0))} -> 12.47 | L501: {=INDEX(DataAll!$AJ$2:$AJ$555,MATCH(LOWER(Data!A501),LOWER(DataAll!$AI$2:$AI$555),0))} -> 28.62 | M501: {=INDEX(DataAll!$AP$2:$AP$555,MATCH(LOWER(Data!A501),LOWER(DataAll!$AO$2:$AO$555),0))} -> 67.97 | N501: {=INDEX(DataAll!$AQ$2:$AQ$555,MATCH(LOWER(Data!A501),LOWER(DataAll!$AO$2:$AO$555),0))} -> 71.92 | O501: {=INDEX(DataAll!$AT$2:$AT$555,MATCH(LOWER(Data!A501),LOWER(DataAll!$AS$2:$AS$555),0))} -> 9.09 | P501: {=INDEX(DataAll!$AU$2:$AU$555,MATCH(LOWER(Data!A501),LOWER(DataAll!$AS$2:$AS$555),0))} -> 8.42 | Q501: {=INDEX(DataAll!$AX$2:$AX$556,MATCH(LOWER(Data!A501),LOWER(DataAll!$AW$2:$AW$556),0))} -> 30.21 | R501: {=INDEX('Longitude and Latitude'!$B$2:$B$579,MATCH(LOWER(Data!A501),LOWER('Longitude and Latitude'!$A$2:$A$579),0))} -> 1.3121235 | S501: {=INDEX('Longitude and Latitude'!$C$2:$C$579,MATCH(LOWER(Data!A501),LOWER('Longitude and Latitude'!$A$2:$A$579),0))} -> 128.48499 | T501: =IF(EXACT(A501, UPPER(A501)), TRUE, FALSE) -> FALSE
A502: Pulau Morotai | B502: 71.58 | C502: {=INDEX(DataAll!$E$2:$E$555,MATCH(LOWER(Data!A502),LOWER(DataAll!$D$2:$D$555),0))} -> 54.56 | D502: {=INDEX(DataAll!$H$2:$H$579,MATCH(LOWER(Data!A502),LOWER(DataAll!$G$2:$G$555),0))} -> 0.556 | E502: {=INDEX(DataAll!$K$2:$K$579,MATCH(LOWER(Data!A502),LOWER(DataAll!$J$2:$J$555),0))} -> 10 | F502: {=INDEX(DataAll!$N$2:$N$555,MATCH(LOWER(Data!A502),LOWER(DataAll!$M$2:$M$555),0))} -> 40.41 | G502: {=INDEX(DataAll!$Q$2:$Q$555,MATCH(LOWER(Data!A502),LOWER(DataAll!$P$2:$P$555),0))} -> 30.64 | H502: {=INDEX(DataAll!$T$2:$T$555,MATCH(LOWER(Data!A502),LOWER(DataAll!$S$2:$S$555),0))} -> 0.336 | I502: {=INDEX(DataAll!$W$2:$W$555,MATCH(LOWER(Data!A502),LOWER(DataAll!$V$2:$V$555),0))} -> 27.13 | J502: {=INDEX(DataAll!$Z$2:$Z$555,MATCH(LOWER(Data!A502),LOWER(DataAll!$Y$2:$Y$555),0))} -> 2.95 | K502: {=INDEX(DataAll!$AM$2:$AM$555,MATCH(LOWER(Data!A502),LOWER(DataAll!$AL$2:$AL$555),0))} -> 5.38 | L502: {=INDEX(DataAll!$AJ$2:$AJ$555,MATCH(LOWER(Data!A502),LOWER(DataAll!$AI$2:$AI$555),0))} -> 35.26 | M502: {=INDEX(DataAll!$AP$2:$AP$555,MATCH(LOWER(Data!A502),LOWER(DataAll!$AO$2:$AO$555),0))} -> 66.16 | N502: {=INDEX(DataAll!$AQ$2:$AQ$555,MATCH(LOWER(Data!A502),LOWER(DataAll!$AO$2:$AO$555),0))} -> 70.15 | O502: {=INDEX(DataAll!$AT$2:$AT$555,MATCH(LOWER(Data!A502),LOWER(DataAll!$AS$2:$AS$555),0))} -> 8.03 | P502: {=INDEX(DataAll!$AU$2:$AU$555,MATCH(LOWER(Data!A502),LOWER(DataAll!$AS$2:$AS$555),0))} -> 7.08 | Q502: {=INDEX(DataAll!$AX$2:$AX$556,MATCH(LOWER(Data!A502),LOWER(DataAll!$AW$2:$AW$556),0))} -> 26.21 | R502: {=INDEX('Longitude and Latitude'!$B$2:$B$579,MATCH(LOWER(Data!A502),LOWER('Longitude and Latitude'!$A$2:$A$579),0))} -> 2 | S502: {=INDEX('Longitude and Latitude'!$C$2:$C$579,MATCH(LOWER(Data!A502),LOWER('Longitude and Latitude'!$A$2:$A$579),0))} -> 128 | T502: =IF(EXACT(A502, UPPER(A502)), TRUE, FALSE) -> FALSE
A503: Pulau Taliabu | B503: 84.51 | C503: {=INDEX(DataAll!$E$2:$E$555,MATCH(LOWER(Data!A503),LOWER(DataAll!$D$2:$D$555),0))} -> 58.6 | D503: {=INDEX(DataAll!$H$2:$H$579,MATCH(LOWER(Data!A503),LOWER(DataAll!$G$2:$G$555),0))} -> 0.617 | E503: {=INDEX(DataAll!$K$2:$K$579,MATCH(LOWER(Data!A503),LOWER(DataAll!$J$2:$J$555),0))} -> 25 | F503: {=INDEX(DataAll!$N$2:$N$555,MATCH(LOWER(Data!A503),LOWER(DataAll!$M$2:$M$555),0))} -> 50.34 | G503: {=INDEX(DataAll!$Q$2:$Q$555,MATCH(LOWER(Data!A503),LOWER(DataAll!$P$2:$P$555),0))} -> 39.21 | H503: {=INDEX(DataAll!$T$2:$T$555,MATCH(LOWER(Data!A503),LOWER(DataAll!$S$2:$S$555),0))} -> 0.362 | I503: {=INDEX(DataAll!$W$2:$W$555,MATCH(LOWER(Data!A503),LOWER(DataAll!$V$2:$V$555),0))} -> 13 | J503: {=INDEX(DataAll!$Z$2:$Z$555,MATCH(LOWER(Data!A503),LOWER(DataAll!$Y$2:$Y$555),0))} -> 2.41 | K503: {=INDEX(DataAll!$AM$2:$AM$555,MATCH(LOWER(Data!A503),LOWER(DataAll!$AL$2:$AL$555),0))} -> 7.31 | L503: {=INDEX(DataAll!$AJ$2:$AJ$555,MATCH(LOWER(Data!A503),LOWER(DataAll!$AI$2:$AI$555),0))} -> 33.12 | M503: {=INDEX(DataAll!$AP$2:$AP$555,MATCH(LOWER(Data!A503),LOWER(DataAll!$AO$2:$AO$555),0))} -> 60.95 | N503: {=INDEX(DataAll!$AQ$2:$AQ$555,MATCH(LOWER(Data!A503),LOWER(DataAll!$AO$2:$AO$555),0))} -> 64.72 | O503: {=INDEX(DataAll!$AT$2:$AT$555,MATCH(LOWER(Data!A503),LOWER(DataAll!$AS$2:$AS$555),0))} -> 8.33 | P503: {=INDEX(DataAll!$AU$2:$AU$555,MATCH(LOWER(Data!A503),LOWER(DataAll!$AS$2:$AS$555),0))} -> 7.76 | Q503: {=INDEX(DataAll!$AX$2:$AX$556,MATCH(LOWER(Data!A503),LOWER(DataAll!$AW$2:$AW$556),0))} -> 22.37 | R503: {=INDEX('Longitude and Latitude'!$B$2:$B$579,MATCH(LOWER(Data!A503),LOWER('Longitude and Latitude'!$A$2:$A$579),0))} -> -1.8 | S503: {=INDEX('Longitude and Latitude'!$C$2:$C$579,MATCH(LOWER(Data!A503),LOWER('Longitude and Latitude'!$A$2:$A$579),0))} -> 124.8 | T503: =IF(EXACT(A503, UPPER(A503)), TRUE, FALSE) -> FALSE
